2025-07-11 09:30:28,228 - ERROR - Exception occurred:
Traceback (most recent call last):
  File "C:\Users\dtumanyan\Desktop\Springbrook Upload\app.py", line 161, in process_file
    main()
  File "C:\Users\dtumanyan\Desktop\Springbrook Upload\utils.py", line 80, in main
    export_df, rni_df = load_data(date_suffix)
TypeError: load_data() missing 1 required positional argument: 'rni_file'

2025-07-11 09:32:14,234 - ERROR - Exception occurred:
Traceback (most recent call last):
  File "C:\Users\dtumanyan\Desktop\Springbrook Upload\app.py", line 161, in process_file
    main()
TypeError: main() missing 2 required positional arguments: 'export_file' and 'rni_file'

2025-07-11 09:38:45,543 - ERROR - Exception occurred:
Traceback (most recent call last):
  File "C:\Users\dtumanyan\Desktop\Springbrook Upload\SBUploadEnv\lib\site-packages\pandas\core\indexes\base.py", line 3812, in get_loc
    return self._engine.get_loc(casted_key)
  File "pandas/_libs/index.pyx", line 167, in pandas._libs.index.IndexEngine.get_loc
  File "pandas/_libs/index.pyx", line 196, in pandas._libs.index.IndexEngine.get_loc
  File "pandas/_libs/hashtable_class_helper.pxi", line 7088, in pandas._libs.hashtable.PyObjectHashTable.get_item
  File "pandas/_libs/hashtable_class_helper.pxi", line 7096, in pandas._libs.hashtable.PyObjectHashTable.get_item
KeyError: 'Meter ID'

The above exception was the direct cause of the following exception:

Traceback (most recent call last):
  File "C:\Users\dtumanyan\Desktop\Springbrook Upload\app.py", line 161, in process_file
    main(self.export_file_path, self.rni_file_path)
  File "C:\Users\dtumanyan\Desktop\Springbrook Upload\utils.py", line 81, in main
    export_df, rni_df = preprocess_data(export_df, rni_df)
  File "C:\Users\dtumanyan\Desktop\Springbrook Upload\utils.py", line 38, in preprocess_data
    rni_df['Meter ID'] = rni_df['Meter ID'].apply(clean_meter_id)
  File "C:\Users\dtumanyan\Desktop\Springbrook Upload\SBUploadEnv\lib\site-packages\pandas\core\frame.py", line 4107, in __getitem__
    indexer = self.columns.get_loc(key)
  File "C:\Users\dtumanyan\Desktop\Springbrook Upload\SBUploadEnv\lib\site-packages\pandas\core\indexes\base.py", line 3819, in get_loc
    raise KeyError(key) from err
KeyError: 'Meter ID'

2025-07-11 09:41:16,961 - ERROR - Exception occurred:
Traceback (most recent call last):
  File "C:\Users\dtumanyan\Desktop\Springbrook Upload\SBUploadEnv\lib\site-packages\pandas\core\indexes\base.py", line 3812, in get_loc
    return self._engine.get_loc(casted_key)
  File "pandas/_libs/index.pyx", line 167, in pandas._libs.index.IndexEngine.get_loc
  File "pandas/_libs/index.pyx", line 196, in pandas._libs.index.IndexEngine.get_loc
  File "pandas/_libs/hashtable_class_helper.pxi", line 7088, in pandas._libs.hashtable.PyObjectHashTable.get_item
  File "pandas/_libs/hashtable_class_helper.pxi", line 7096, in pandas._libs.hashtable.PyObjectHashTable.get_item
KeyError: 'Meter ID'

The above exception was the direct cause of the following exception:

Traceback (most recent call last):
  File "C:\Users\dtumanyan\Desktop\Springbrook Upload\app.py", line 161, in process_file
    main(self.export_file_path, self.rni_file_path)
  File "C:\Users\dtumanyan\Desktop\Springbrook Upload\utils.py", line 81, in main
    export_df, rni_df = preprocess_data(export_df, rni_df)
  File "C:\Users\dtumanyan\Desktop\Springbrook Upload\utils.py", line 38, in preprocess_data
    rni_df['Meter ID'] = rni_df['Meter ID'].apply(clean_meter_id)
  File "C:\Users\dtumanyan\Desktop\Springbrook Upload\SBUploadEnv\lib\site-packages\pandas\core\frame.py", line 4107, in __getitem__
    indexer = self.columns.get_loc(key)
  File "C:\Users\dtumanyan\Desktop\Springbrook Upload\SBUploadEnv\lib\site-packages\pandas\core\indexes\base.py", line 3819, in get_loc
    raise KeyError(key) from err
KeyError: 'Meter ID'

2025-07-11 09:51:43,354 - ERROR - Exception occurred:
Traceback (most recent call last):
  File "C:\Users\dtumanyan\Desktop\Springbrook Upload\SBUploadEnv\lib\site-packages\pandas\core\indexes\base.py", line 3812, in get_loc
    return self._engine.get_loc(casted_key)
  File "pandas/_libs/index.pyx", line 167, in pandas._libs.index.IndexEngine.get_loc
  File "pandas/_libs/index.pyx", line 196, in pandas._libs.index.IndexEngine.get_loc
  File "pandas/_libs/hashtable_class_helper.pxi", line 7088, in pandas._libs.hashtable.PyObjectHashTable.get_item
  File "pandas/_libs/hashtable_class_helper.pxi", line 7096, in pandas._libs.hashtable.PyObjectHashTable.get_item
KeyError: 'SerialNumber'

The above exception was the direct cause of the following exception:

Traceback (most recent call last):
  File "C:\Users\dtumanyan\Desktop\Springbrook Upload\app.py", line 161, in process_file
    main(self.export_file_path, self.rni_file_path)
  File "C:\Users\dtumanyan\Desktop\Springbrook Upload\utils.py", line 81, in main
    export_df, rni_df = preprocess_data(export_df, rni_df)
  File "C:\Users\dtumanyan\Desktop\Springbrook Upload\utils.py", line 40, in preprocess_data
    export_df['SerialNumber'] = export_df['SerialNumber'].astype(str)
  File "C:\Users\dtumanyan\Desktop\Springbrook Upload\SBUploadEnv\lib\site-packages\pandas\core\frame.py", line 4107, in __getitem__
    indexer = self.columns.get_loc(key)
  File "C:\Users\dtumanyan\Desktop\Springbrook Upload\SBUploadEnv\lib\site-packages\pandas\core\indexes\base.py", line 3819, in get_loc
    raise KeyError(key) from err
KeyError: 'SerialNumber'

